Workbook
Name SF9Learners: _SF9_LEARNER_LIST!$A$1:INDEX(_SF9_LEARNER_LIST!$A$1:$A$100,MAX(1,COUNTIF(_SF9_LEARNER_LIST!$A$1:$A$100,"?*")))

Sheet Home

Sheet INPUT DATA
A1: Input Data Sheet for Electronic-Class Record (ECR) for Class Adviser
B7: SCHOOL INFORMATION | J7: LEARNERS' DATA
C10: REGION | E10: : | K10: MALE | M10: LRN | N10: BIRTHDATE | P10: FEMALE | R10: LRN | S10: BIRTHDATE
C11: DIVISION | E11: : | K11: 1 | P11: 1
C12: CITY/MUNICIPALITY | E12: : | K12: 2 | P12: 2
C13: DISTRICT | E13: : | K13: 3 | P13: 3
K14: 4 | P14: 4
C15: SCHOOL ID | E15: : | K15: 5 | P15: 5
C16: SCHOOL NAME | E16: : | K16: 6 | P16: 6
K17: 7 | P17: 7
C18: SCHOOL YEAR | E18: : | K18: 8 | P18: 8
C19: SCHOOL HEAD | E19: : | K19: 9 | P19: 9
K20: 10 | P20: 10
K21: 11 | P21: 11
K22: 12 | P22: 12
B23: TEACHER, GRADE LEVEL, SECTION INFORMATION | K23: 13 | P23: 13
K24: 14 | P24: 14
K25: 15 | P25: 15
C26: ADVISER | E26: : | K26: 16 | P26: 16
C27: GRADE LEVEL | E27: : | G27: (Accepts Kinder only) | K27: 17 | P27: 17
C28: SECTION | E28: : | K28: 18 | P28: 18
K29: 19 | P29: 19
C30: IMPORTANT NOTE: This is the official and final version of the file. All tabs are password-protected to prevent accidental formula edits and maintain the accuracy and integrity of the data. If you identify any inconsistencies or issues, particularly with the formulas, please report them for appropriate review and necessary correction. | K30: 20 | P30: 20
K31: 21 | P31: 21
K32: 22 | P32: 22
K33: 23 | P33: 23
K34: 24 | P34: 24
K35: 25 | P35: 25
K36: 26 | P36: 26
K37: 27 | P37: 27
K38: 28 | P38: 28
K39: 29 | P39: 29
K40: 30 | P40: 30
K41: 31 | P41: 31
K42: 32 | P42: 32
... K60: 50 | P60: 50
T62: 2026_v1.0

Sheet TERM 1 SUMMARY
A1: CLASS SUMMARY - FIRST
D5: REGION | E5: ='INPUT DATA'!F10 -> 0 | I5: DIVISION | K5: ='INPUT DATA'!F11 -> 0
D6: SCHOOL NAME | E6: ='INPUT DATA'!F16 -> 0 | I6: SCHOOL ID | K6: ='INPUT DATA'!F15 -> 0 | S6: SCHOOL YEAR | T6: ='INPUT DATA'!F18 -> 0
B9: FIRST TERM | I9: Age (BoSY) | K9: Age (EoSY) | M9: Sex | N9: GRADE LEVEL | R9: ='INPUT DATA'!F27 -> 0 | AE9: ADVISER | AH9: ='INPUT DATA'!F26 -> 0
N10: SECTION | R10: ='INPUT DATA'!F28 -> 0
N11: I. Sensory Perceptual and Motor Development | S11: II. Socio-emotional Development | Z11: III. Cognitive Development | AT11: IV. Language, Literacy, and Communication Development
B12: LEARNERS' NAMES | F12: LRN | H12: Date of Birth | I12: Years | J12: Months | K12: Years | L12: Months | N12: 1 | O12: 2 | P12: 3 | Q12: 4 | R12: 5 | S12: 1 | T12: 2 | U12: 3 | V12: 4 | W12: 5 | X12: 6 | Y12: 7 | Z12: 1 | AA12: 2 | AB12: 3 | AC12: 4 | AD12: 5 | AE12: 6 | AF12: 7 | AG12: 8 | AH12: 9 | AI12: 10 | AJ12: 11 | AK12: 12 | AL12: 13 | AM12: 14 | AN12: 15 | AO12: 16 | AP12: 17 | AQ12: 18 | AR12: 19 | AS12: 20 | AT12: A. Listening and Viewing | AX12: B. Sight Word Recognition | AZ12: C. Speaking | BF12: D. Reading | BL12: E. Comprehension | BN12: F. Concepts of Print | BQ12: G. Writing
AT13: 1 | AU13: 2 | AV13: 3 | AW13: 4 | AX13: 5 | AY13: 6 | AZ13: 7 | BA13: 8 | BB13: 9 | BC13: 10 | BD13: 11 | BE13: 12 | BF13: Phonological / Phonemic Awareness | BG13: Letter Knowledge | BJ13: Letter Sound Relationship | BL13: 19 | BM13: 20 | BN13: 21 | BO13: 22 | BP13: 23 | BQ13: 24 | BR13: 25 | BS13: 26 | BT13: 27 | BU13: 28
BF14: 13 | BG14: 14 | BH14: 15 | BI14: 16 | BJ14: 17 | BK14: 18
B15: MALE
B16: 1 | C16: =IF('INPUT DATA'!L11="","",'INPUT DATA'!L11) | F16: =IF('INPUT DATA'!M11="","",'INPUT DATA'!M11) | H16: =IF('INPUT DATA'!N11="","",'INPUT DATA'!N11) | I16: =IF(H16="","",DATEDIF(H16,DATE(2026,6,8),"Y")) | J16: =IF(H16="","",DATEDIF(H16,DATE(2026,6,8),"YM")) | K16: =IF(H16="","",DATEDIF(H16,DATE(2027,4,8),"Y")) | L16: =IF(H16="","",DATEDIF(H16,DATE(2027,4,8),"YM")) | M16: M
B17: 2 | C17: =IF('INPUT DATA'!L12="","",'INPUT DATA'!L12) | F17: =IF('INPUT DATA'!M12="","",'INPUT DATA'!M12) | H17: =IF('INPUT DATA'!N12="","",'INPUT DATA'!N12) | I17: =IF(H17="","",DATEDIF(H17,DATE(2026,6,8),"Y")) | J17: =IF(H17="","",DATEDIF(H17,DATE(2026,6,8),"YM")) | K17: =IF(H17="","",DATEDIF(H17,DATE(2027,4,8),"Y")) | L17: =IF(H17="","",DATEDIF(H17,DATE(2027,4,8),"YM")) | M17: M
B18: 3 | C18: =IF('INPUT DATA'!L13="","",'INPUT DATA'!L13) | F18: =IF('INPUT DATA'!M13="","",'INPUT DATA'!M13) | H18: =IF('INPUT DATA'!N13="","",'INPUT DATA'!N13) | I18: =IF(H18="","",DATEDIF(H18,DATE(2026,6,8),"Y")) | J18: =IF(H18="","",DATEDIF(H18,DATE(2026,6,8),"YM")) | K18: =IF(H18="","",DATEDIF(H18,DATE(2027,4,8),"Y")) | L18: =IF(H18="","",DATEDIF(H18,DATE(2027,4,8),"YM")) | M18: M
B19: 4 | C19: =IF('INPUT DATA'!L14="","",'INPUT DATA'!L14) | F19: =IF('INPUT DATA'!M14="","",'INPUT DATA'!M14) | H19: =IF('INPUT DATA'!N14="","",'INPUT DATA'!N14) | I19: =IF(H19="","",DATEDIF(H19,DATE(2026,6,8),"Y")) | J19: =IF(H19="","",DATEDIF(H19,DATE(2026,6,8),"YM")) | K19: =IF(H19="","",DATEDIF(H19,DATE(2027,4,8),"Y")) | L19: =IF(H19="","",DATEDIF(H19,DATE(2027,4,8),"YM")) | M19: M
B20: 5 | C20: =IF('INPUT DATA'!L15="","",'INPUT DATA'!L15) | F20: =IF('INPUT DATA'!M15="","",'INPUT DATA'!M15) | H20: =IF('INPUT DATA'!N15="","",'INPUT DATA'!N15) | I20: =IF(H20="","",DATEDIF(H20,DATE(2026,6,8),"Y")) | J20: =IF(H20="","",DATEDIF(H20,DATE(2026,6,8),"YM")) | K20: =IF(H20="","",DATEDIF(H20,DATE(2027,4,8),"Y")) | L20: =IF(H20="","",DATEDIF(H20,DATE(2027,4,8),"YM")) | M20: M
B21: 6 | C21: =IF('INPUT DATA'!L16="","",'INPUT DATA'!L16) | F21: =IF('INPUT DATA'!M16="","",'INPUT DATA'!M16) | H21: =IF('INPUT DATA'!N16="","",'INPUT DATA'!N16) | I21: =IF(H21="","",DATEDIF(H21,DATE(2026,6,8),"Y")) | J21: =IF(H21="","",DATEDIF(H21,DATE(2026,6,8),"YM")) | K21: =IF(H21="","",DATEDIF(H21,DATE(2027,4,8),"Y")) | L21: =IF(H21="","",DATEDIF(H21,DATE(2027,4,8),"YM")) | M21: M
B22: 7 | C22: =IF('INPUT DATA'!L17="","",'INPUT DATA'!L17) | F22: =IF('INPUT DATA'!M17="","",'INPUT DATA'!M17) | H22: =IF('INPUT DATA'!N17="","",'INPUT DATA'!N17) | I22: =IF(H22="","",DATEDIF(H22,DATE(2026,6,8),"Y")) | J22: =IF(H22="","",DATEDIF(H22,DATE(2026,6,8),"YM")) | K22: =IF(H22="","",DATEDIF(H22,DATE(2027,4,8),"Y")) | L22: =IF(H22="","",DATEDIF(H22,DATE(2027,4,8),"YM")) | M22: M
B23: 8 | C23: =IF('INPUT DATA'!L18="","",'INPUT DATA'!L18) | F23: =IF('INPUT DATA'!M18="","",'INPUT DATA'!M18) | H23: =IF('INPUT DATA'!N18="","",'INPUT DATA'!N18) | I23: =IF(H23="","",DATEDIF(H23,DATE(2026,6,8),"Y")) | J23: =IF(H23="","",DATEDIF(H23,DATE(2026,6,8),"YM")) | K23: =IF(H23="","",DATEDIF(H23,DATE(2027,4,8),"Y")) | L23: =IF(H23="","",DATEDIF(H23,DATE(2027,4,8),"YM")) | M23: M
B24: 9 | C24: =IF('INPUT DATA'!L19="","",'INPUT DATA'!L19) | F24: =IF('INPUT DATA'!M19="","",'INPUT DATA'!M19) | H24: =IF('INPUT DATA'!N19="","",'INPUT DATA'!N19) | I24: =IF(H24="","",DATEDIF(H24,DATE(2026,6,8),"Y")) | J24: =IF(H24="","",DATEDIF(H24,DATE(2026,6,8),"YM")) | K24: =IF(H24="","",DATEDIF(H24,DATE(2027,4,8),"Y")) | L24: =IF(H24="","",DATEDIF(H24,DATE(2027,4,8),"YM")) | M24: M
B25: 10 | C25: =IF('INPUT DATA'!L20="","",'INPUT DATA'!L20) | F25: =IF('INPUT DATA'!M20="","",'INPUT DATA'!M20) | H25: =IF('INPUT DATA'!N20="","",'INPUT DATA'!N20) | I25: =IF(H25="","",DATEDIF(H25,DATE(2026,6,8),"Y")) | J25: =IF(H25="","",DATEDIF(H25,DATE(2026,6,8),"YM")) | K25: =IF(H25="","",DATEDIF(H25,DATE(2027,4,8),"Y")) | L25: =IF(H25="","",DATEDIF(H25,DATE(2027,4,8),"YM")) | M25: M
B26: 11 | C26: =IF('INPUT DATA'!L21="","",'INPUT DATA'!L21) | F26: =IF('INPUT DATA'!M21="","",'INPUT DATA'!M21) | H26: =IF('INPUT DATA'!N21="","",'INPUT DATA'!N21) | I26: =IF(H26="","",DATEDIF(H26,DATE(2026,6,8),"Y")) | J26: =IF(H26="","",DATEDIF(H26,DATE(2026,6,8),"YM")) | K26: =IF(H26="","",DATEDIF(H26,DATE(2027,4,8),"Y")) | L26: =IF(H26="","",DATEDIF(H26,DATE(2027,4,8),"YM")) | M26: M
B27: 12 | C27: =IF('INPUT DATA'!L22="","",'INPUT DATA'!L22) | F27: =IF('INPUT DATA'!M22="","",'INPUT DATA'!M22) | H27: =IF('INPUT DATA'!N22="","",'INPUT DATA'!N22) | I27: =IF(H27="","",DATEDIF(H27,DATE(2026,6,8),"Y")) | J27: =IF(H27="","",DATEDIF(H27,DATE(2026,6,8),"YM")) | K27: =IF(H27="","",DATEDIF(H27,DATE(2027,4,8),"Y")) | L27: =IF(H27="","",DATEDIF(H27,DATE(2027,4,8),"YM")) | M27: M
... B64: 50 | C64: =IF('INPUT DATA'!L59="","",'INPUT DATA'!L59) | F64: =IF('INPUT DATA'!M59="","",'INPUT DATA'!M59) | H64: =IF('INPUT DATA'!N59="","",'INPUT DATA'!N59) | I64: =IF(H64="","",DATEDIF(H64,DATE(2026,6,8),"Y")) | J64: =IF(H64="","",DATEDIF(H64,DATE(2026,6,8),"YM")) | K64: =IF(H64="","",DATEDIF(H64,DATE(2027,4,8),"Y")) | L64: =IF(H64="","",DATEDIF(H64,DATE(2027,4,8),"YM")) | M64: M
B65: FEMALE
B66: 1 | C66: =IF('INPUT DATA'!Q11="","",'INPUT DATA'!Q11) | F66: =IF('INPUT DATA'!R11="","",'INPUT DATA'!R11) | H66: =IF('INPUT DATA'!S11="","",'INPUT DATA'!S11) | I66: =IF(H66="","",DATEDIF(H66,DATE(2026,6,8),"Y")) | J66: =IF(H66="","",DATEDIF(H66,DATE(2026,6,8),"YM")) | K66: =IF(H66="","",DATEDIF(H66,DATE(2027,4,8),"Y")) | L66: =IF(H66="","",DATEDIF(H66,DATE(2027,4,8),"YM")) | M66: F
B67: 2 | C67: =IF('INPUT DATA'!Q12="","",'INPUT DATA'!Q12) | F67: =IF('INPUT DATA'!R12="","",'INPUT DATA'!R12) | H67: =IF('INPUT DATA'!S12="","",'INPUT DATA'!S12) | I67: =IF(H67="","",DATEDIF(H67,DATE(2026,6,8),"Y")) | J67: =IF(H67="","",DATEDIF(H67,DATE(2026,6,8),"YM")) | K67: =IF(H67="","",DATEDIF(H67,DATE(2027,4,8),"Y")) | L67: =IF(H67="","",DATEDIF(H67,DATE(2027,4,8),"YM")) | M67: F
B68: 3 | C68: =IF('INPUT DATA'!Q13="","",'INPUT DATA'!Q13) | F68: =IF('INPUT DATA'!R13="","",'INPUT DATA'!R13) | H68: =IF('INPUT DATA'!S13="","",'INPUT DATA'!S13) | I68: =IF(H68="","",DATEDIF(H68,DATE(2026,6,8),"Y")) | J68: =IF(H68="","",DATEDIF(H68,DATE(2026,6,8),"YM")) | K68: =IF(H68="","",DATEDIF(H68,DATE(2027,4,8),"Y")) | L68: =IF(H68="","",DATEDIF(H68,DATE(2027,4,8),"YM")) | M68: F
B69: 4 | C69: =IF('INPUT DATA'!Q14="","",'INPUT DATA'!Q14) | F69: =IF('INPUT DATA'!R14="","",'INPUT DATA'!R14) | H69: =IF('INPUT DATA'!S14="","",'INPUT DATA'!S14) | I69: =IF(H69="","",DATEDIF(H69,DATE(2026,6,8),"Y")) | J69: =IF(H69="","",DATEDIF(H69,DATE(2026,6,8),"YM")) | K69: =IF(H69="","",DATEDIF(H69,DATE(2027,4,8),"Y")) | L69: =IF(H69="","",DATEDIF(H69,DATE(2027,4,8),"YM")) | M69: F
B70: 5 | C70: =IF('INPUT DATA'!Q15="","",'INPUT DATA'!Q15) | F70: =IF('INPUT DATA'!R15="","",'INPUT DATA'!R15) | H70: =IF('INPUT DATA'!S15="","",'INPUT DATA'!S15) | I70: =IF(H70="","",DATEDIF(H70,DATE(2026,6,8),"Y")) | J70: =IF(H70="","",DATEDIF(H70,DATE(2026,6,8),"YM")) | K70: =IF(H70="","",DATEDIF(H70,DATE(2027,4,8),"Y")) | L70: =IF(H70="","",DATEDIF(H70,DATE(2027,4,8),"YM")) | M70: F
B71: 6 | C71: =IF('INPUT DATA'!Q16="","",'INPUT DATA'!Q16) | F71: =IF('INPUT DATA'!R16="","",'INPUT DATA'!R16) | H71: =IF('INPUT DATA'!S16="","",'INPUT DATA'!S16) | I71: =IF(H71="","",DATEDIF(H71,DATE(2026,6,8),"Y")) | J71: =IF(H71="","",DATEDIF(H71,DATE(2026,6,8),"YM")) | K71: =IF(H71="","",DATEDIF(H71,DATE(2027,4,8),"Y")) | L71: =IF(H71="","",DATEDIF(H71,DATE(2027,4,8),"YM")) | M71: F
B72: 7 | C72: =IF('INPUT DATA'!Q17="","",'INPUT DATA'!Q17) | F72: =IF('INPUT DATA'!R17="","",'INPUT DATA'!R17) | H72: =IF('INPUT DATA'!S17="","",'INPUT DATA'!S17) | I72: =IF(H72="","",DATEDIF(H72,DATE(2026,6,8),"Y")) | J72: =IF(H72="","",DATEDIF(H72,DATE(2026,6,8),"YM")) | K72: =IF(H72="","",DATEDIF(H72,DATE(2027,4,8),"Y")) | L72: =IF(H72="","",DATEDIF(H72,DATE(2027,4,8),"YM")) | M72: F
B73: 8 | C73: =IF('INPUT DATA'!Q18="","",'INPUT DATA'!Q18) | F73: =IF('INPUT DATA'!R18="","",'INPUT DATA'!R18) | H73: =IF('INPUT DATA'!S18="","",'INPUT DATA'!S18) | I73: =IF(H73="","",DATEDIF(H73,DATE(2026,6,8),"Y")) | J73: =IF(H73="","",DATEDIF(H73,DATE(2026,6,8),"YM")) | K73: =IF(H73="","",DATEDIF(H73,DATE(2027,4,8),"Y")) | L73: =IF(H73="","",DATEDIF(H73,DATE(2027,4,8),"YM")) | M73: F
B74: 9 | C74: =IF('INPUT DATA'!Q19="","",'INPUT DATA'!Q19) | F74: =IF('INPUT DATA'!R19="","",'INPUT DATA'!R19) | H74: =IF('INPUT DATA'!S19="","",'INPUT DATA'!S19) | I74: =IF(H74="","",DATEDIF(H74,DATE(2026,6,8),"Y")) | J74: =IF(H74="","",DATEDIF(H74,DATE(2026,6,8),"YM")) | K74: =IF(H74="","",DATEDIF(H74,DATE(2027,4,8),"Y")) | L74: =IF(H74="","",DATEDIF(H74,DATE(2027,4,8),"YM")) | M74: F
B75: 10 | C75: =IF('INPUT DATA'!Q20="","",'INPUT DATA'!Q20) | F75: =IF('INPUT DATA'!R20="","",'INPUT DATA'!R20) | H75: =IF('INPUT DATA'!S20="","",'INPUT DATA'!S20) | I75: =IF(H75="","",DATEDIF(H75,DATE(2026,6,8),"Y")) | J75: =IF(H75="","",DATEDIF(H75,DATE(2026,6,8),"YM")) | K75: =IF(H75="","",DATEDIF(H75,DATE(2027,4,8),"Y")) | L75: =IF(H75="","",DATEDIF(H75,DATE(2027,4,8),"YM")) | M75: F
B76: 11 | C76: =IF('INPUT DATA'!Q21="","",'INPUT DATA'!Q21) | F76: =IF('INPUT DATA'!R21="","",'INPUT DATA'!R21) | H76: =IF('INPUT DATA'!S21="","",'INPUT DATA'!S21) | I76: =IF(H76="","",DATEDIF(H76,DATE(2026,6,8),"Y")) | J76: =IF(H76="","",DATEDIF(H76,DATE(2026,6,8),"YM")) | K76: =IF(H76="","",DATEDIF(H76,DATE(2027,4,8),"Y")) | L76: =IF(H76="","",DATEDIF(H76,DATE(2027,4,8),"YM")) | M76: F
B77: 12 | C77: =IF('INPUT DATA'!Q22="","",'INPUT DATA'!Q22) | F77: =IF('INPUT DATA'!R22="","",'INPUT DATA'!R22) | H77: =IF('INPUT DATA'!S22="","",'INPUT DATA'!S22) | I77: =IF(H77="","",DATEDIF(H77,DATE(2026,6,8),"Y")) | J77: =IF(H77="","",DATEDIF(H77,DATE(2026,6,8),"YM")) | K77: =IF(H77="","",DATEDIF(H77,DATE(2027,4,8),"Y")) | L77: =IF(H77="","",DATEDIF(H77,DATE(2027,4,8),"YM")) | M77: F
... B114: 50 | C114: =IF('INPUT DATA'!Q59="","",'INPUT DATA'!Q59) | F114: =IF('INPUT DATA'!R59="","",'INPUT DATA'!R59) | H114: =IF('INPUT DATA'!S59="","",'INPUT DATA'!S59) | I114: =IF(H114="","",DATEDIF(H114,DATE(2026,6,8),"Y")) | J114: =IF(H114="","",DATEDIF(H114,DATE(2026,6,8),"YM")) | K114: =IF(H114="","",DATEDIF(H114,DATE(2027,4,8),"Y")) | L114: =IF(H114="","",DATEDIF(H114,DATE(2027,4,8),"YM")) | M114: F

Sheet TERM 2 SUMMARY
A1: CLASS SUMMARY - SECOND
D5: REGION | E5: ='INPUT DATA'!F10 -> 0 | I5: DIVISION | K5: ='INPUT DATA'!F11 -> 0
D6: SCHOOL NAME | E6: ='INPUT DATA'!F16 -> 0 | I6: SCHOOL ID | K6: ='INPUT DATA'!F15 -> 0 | S6: SCHOOL YEAR | T6: ='INPUT DATA'!F18 -> 0
B9: SECOND TERM | I9: Age (BoSY) | K9: Age (EoSY) | M9: Sex | N9: GRADE LEVEL | R9: ='INPUT DATA'!F27 -> 0 | AE9: ADVISER | AH9: ='INPUT DATA'!F26 -> 0
N10: SECTION | R10: ='INPUT DATA'!F28 -> 0
N11: I. Sensory Perceptual and Motor Development | S11: II. Socio-emotional Development | Z11: III. Cognitive Development | AT11: IV. Language, Literacy, and Communication Development
B12: LEARNERS' NAMES | F12: LRN | H12: Date of Birth | I12: Years | J12: Months | K12: Years | L12: Months | N12: 1 | O12: 2 | P12: 3 | Q12: 4 | R12: 5 | S12: 1 | T12: 2 | U12: 3 | V12: 4 | W12: 5 | X12: 6 | Y12: 7 | Z12: 1 | AA12: 2 | AB12: 3 | AC12: 4 | AD12: 5 | AE12: 6 | AF12: 7 | AG12: 8 | AH12: 9 | AI12: 10 | AJ12: 11 | AK12: 12 | AL12: 13 | AM12: 14 | AN12: 15 | AO12: 16 | AP12: 17 | AQ12: 18 | AR12: 19 | AS12: 20 | AT12: A. Listening and Viewing | AX12: B. Sight Word Recognition | AZ12: C. Speaking | BF12: D. Reading | BL12: E. Comprehension | BN12: F. Concepts of Print | BQ12: G. Writing
AT13: 1 | AU13: 2 | AV13: 3 | AW13: 4 | AX13: 5 | AY13: 6 | AZ13: 7 | BA13: 8 | BB13: 9 | BC13: 10 | BD13: 11 | BE13: 12 | BF13: Phonological / Phonemic Awareness | BG13: Letter Knowledge | BJ13: Letter Sound Relationship | BL13: 19 | BM13: 20 | BN13: 21 | BO13: 22 | BP13: 23 | BQ13: 24 | BR13: 25 | BS13: 26 | BT13: 27 | BU13: 28
BF14: 13 | BG14: 14 | BH14: 15 | BI14: 16 | BJ14: 17 | BK14: 18
B15: MALE
B16: 1 | C16: =IF('INPUT DATA'!L11="","",'INPUT DATA'!L11) | F16: =IF('INPUT DATA'!M11="","",'INPUT DATA'!M11) | H16: =IF('INPUT DATA'!N11="","",'INPUT DATA'!N11) | I16: =IF(H16="","",DATEDIF(H16,DATE(2026,6,8),"Y")) | J16: =IF(H16="","",DATEDIF(H16,DATE(2026,6,8),"YM")) | K16: =IF(H16="","",DATEDIF(H16,DATE(2027,4,8),"Y")) | L16: =IF(H16="","",DATEDIF(H16,DATE(2027,4,8),"YM")) | M16: M
B17: 2 | C17: =IF('INPUT DATA'!L12="","",'INPUT DATA'!L12) | F17: =IF('INPUT DATA'!M12="","",'INPUT DATA'!M12) | H17: =IF('INPUT DATA'!N12="","",'INPUT DATA'!N12) | I17: =IF(H17="","",DATEDIF(H17,DATE(2026,6,8),"Y")) | J17: =IF(H17="","",DATEDIF(H17,DATE(2026,6,8),"YM")) | K17: =IF(H17="","",DATEDIF(H17,DATE(2027,4,8),"Y")) | L17: =IF(H17="","",DATEDIF(H17,DATE(2027,4,8),"YM")) | M17: M
B18: 3 | C18: =IF('INPUT DATA'!L13="","",'INPUT DATA'!L13) | F18: =IF('INPUT DATA'!M13="","",'INPUT DATA'!M13) | H18: =IF('INPUT DATA'!N13="","",'INPUT DATA'!N13) | I18: =IF(H18="","",DATEDIF(H18,DATE(2026,6,8),"Y")) | J18: =IF(H18="","",DATEDIF(H18,DATE(2026,6,8),"YM")) | K18: =IF(H18="","",DATEDIF(H18,DATE(2027,4,8),"Y")) | L18: =IF(H18="","",DATEDIF(H18,DATE(2027,4,8),"YM")) | M18: M
B19: 4 | C19: =IF('INPUT DATA'!L14="","",'INPUT DATA'!L14) | F19: =IF('INPUT DATA'!M14="","",'INPUT DATA'!M14) | H19: =IF('INPUT DATA'!N14="","",'INPUT DATA'!N14) | I19: =IF(H19="","",DATEDIF(H19,DATE(2026,6,8),"Y")) | J19: =IF(H19="","",DATEDIF(H19,DATE(2026,6,8),"YM")) | K19: =IF(H19="","",DATEDIF(H19,DATE(2027,4,8),"Y")) | L19: =IF(H19="","",DATEDIF(H19,DATE(2027,4,8),"YM")) | M19: M
B20: 5 | C20: =IF('INPUT DATA'!L15="","",'INPUT DATA'!L15) | F20: =IF('INPUT DATA'!M15="","",'INPUT DATA'!M15) | H20: =IF('INPUT DATA'!N15="","",'INPUT DATA'!N15) | I20: =IF(H20="","",DATEDIF(H20,DATE(2026,6,8),"Y")) | J20: =IF(H20="","",DATEDIF(H20,DATE(2026,6,8),"YM")) | K20: =IF(H20="","",DATEDIF(H20,DATE(2027,4,8),"Y")) | L20: =IF(H20="","",DATEDIF(H20,DATE(2027,4,8),"YM")) | M20: M
B21: 6 | C21: =IF('INPUT DATA'!L16="","",'INPUT DATA'!L16) | F21: =IF('INPUT DATA'!M16="","",'INPUT DATA'!M16) | H21: =IF('INPUT DATA'!N16="","",'INPUT DATA'!N16) | I21: =IF(H21="","",DATEDIF(H21,DATE(2026,6,8),"Y")) | J21: =IF(H21="","",DATEDIF(H21,DATE(2026,6,8),"YM")) | K21: =IF(H21="","",DATEDIF(H21,DATE(2027,4,8),"Y")) | L21: =IF(H21="","",DATEDIF(H21,DATE(2027,4,8),"YM")) | M21: M
B22: 7 | C22: =IF('INPUT DATA'!L17="","",'INPUT DATA'!L17) | F22: =IF('INPUT DATA'!M17="","",'INPUT DATA'!M17) | H22: =IF('INPUT DATA'!N17="","",'INPUT DATA'!N17) | I22: =IF(H22="","",DATEDIF(H22,DATE(2026,6,8),"Y")) | J22: =IF(H22="","",DATEDIF(H22,DATE(2026,6,8),"YM")) | K22: =IF(H22="","",DATEDIF(H22,DATE(2027,4,8),"Y")) | L22: =IF(H22="","",DATEDIF(H22,DATE(2027,4,8),"YM")) | M22: M
B23: 8 | C23: =IF('INPUT DATA'!L18="","",'INPUT DATA'!L18) | F23: =IF('INPUT DATA'!M18="","",'INPUT DATA'!M18) | H23: =IF('INPUT DATA'!N18="","",'INPUT DATA'!N18) | I23: =IF(H23="","",DATEDIF(H23,DATE(2026,6,8),"Y")) | J23: =IF(H23="","",DATEDIF(H23,DATE(2026,6,8),"YM")) | K23: =IF(H23="","",DATEDIF(H23,DATE(2027,4,8),"Y")) | L23: =IF(H23="","",DATEDIF(H23,DATE(2027,4,8),"YM")) | M23: M
B24: 9 | C24: =IF('INPUT DATA'!L19="","",'INPUT DATA'!L19) | F24: =IF('INPUT DATA'!M19="","",'INPUT DATA'!M19) | H24: =IF('INPUT DATA'!N19="","",'INPUT DATA'!N19) | I24: =IF(H24="","",DATEDIF(H24,DATE(2026,6,8),"Y")) | J24: =IF(H24="","",DATEDIF(H24,DATE(2026,6,8),"YM")) | K24: =IF(H24="","",DATEDIF(H24,DATE(2027,4,8),"Y")) | L24: =IF(H24="","",DATEDIF(H24,DATE(2027,4,8),"YM")) | M24: M
B25: 10 | C25: =IF('INPUT DATA'!L20="","",'INPUT DATA'!L20) | F25: =IF('INPUT DATA'!M20="","",'INPUT DATA'!M20) | H25: =IF('INPUT DATA'!N20="","",'INPUT DATA'!N20) | I25: =IF(H25="","",DATEDIF(H25,DATE(2026,6,8),"Y")) | J25: =IF(H25="","",DATEDIF(H25,DATE(2026,6,8),"YM")) | K25: =IF(H25="","",DATEDIF(H25,DATE(2027,4,8),"Y")) | L25: =IF(H25="","",DATEDIF(H25,DATE(2027,4,8),"YM")) | M25: M
B26: 11 | C26: =IF('INPUT DATA'!L21="","",'INPUT DATA'!L21) | F26: =IF('INPUT DATA'!M21="","",'INPUT DATA'!M21) | H26: =IF('INPUT DATA'!N21="","",'INPUT DATA'!N21) | I26: =IF(H26="","",DATEDIF(H26,DATE(2026,6,8),"Y")) | J26: =IF(H26="","",DATEDIF(H26,DATE(2026,6,8),"YM")) | K26: =IF(H26="","",DATEDIF(H26,DATE(2027,4,8),"Y")) | L26: =IF(H26="","",DATEDIF(H26,DATE(2027,4,8),"YM")) | M26: M
B27: 12 | C27: =IF('INPUT DATA'!L22="","",'INPUT DATA'!L22) | F27: =IF('INPUT DATA'!M22="","",'INPUT DATA'!M22) | H27: =IF('INPUT DATA'!N22="","",'INPUT DATA'!N22) | I27: =IF(H27="","",DATEDIF(H27,DATE(2026,6,8),"Y")) | J27: =IF(H27="","",DATEDIF(H27,DATE(2026,6,8),"YM")) | K27: =IF(H27="","",DATEDIF(H27,DATE(2027,4,8),"Y")) | L27: =IF(H27="","",DATEDIF(H27,DATE(2027,4,8),"YM")) | M27: M
... B50: 36 | C50: =IF('INPUT DATA'!L45="","",'INPUT DATA'!L45) | F50: =IF('INPUT DATA'!M45="","",'INPUT DATA'!M45) | H50: =IF('INPUT DATA'!N45="","",'INPUT DATA'!N45) | I50: =IF(H50="","",DATEDIF(H50,DATE(2026,6,8),"Y")) | J50: =IF(H50="","",DATEDIF(H50,DATE(2026,6,8),"YM")) | K50: =IF(H50="","",DATEDIF(H50,DATE(2027,4,8),"Y")) | L50: =IF(H50="","",DATEDIF(H50,DATE(2027,4,8),"YM")) | M50: M
B51: 37 | C51: =IF('INPUT DATA'!L46="","",'INPUT DATA'!L46) | F51: =IF('INPUT DATA'!M46="","",'INPUT DATA'!M46) | H51: =IF('INPUT DATA'!N46="","",'INPUT DATA'!N46) | I51: =IFERROR(IF(OR(H51="",H51=0),"",DATEDIF(IF(ISNUMBER(H51),H51,DATEVALUE(H51)),DATE(VALUE(LEFT('INPUT DATA'!$F$18,4)),6,1),"Y")),"") | J51: =IFERROR(IF(OR(H51="",H51=0),"",DATEDIF(IF(ISNUMBER(H51),H51,DATEVALUE(H51)),DATE(VALUE(LEFT('INPUT DATA'!$F$18,4)),6,1),"YM")),"") | K51: =IFERROR(IF(OR(H51="",H51=0),"",DATEDIF(IF(ISNUMBER(H51),H51,DATEVALUE(H51)),DATE(VALUE(RIGHT('INPUT DATA'!$F$18,4)),5,31),"Y")),"") | L51: =IFERROR(IF(OR(H51="",H51=0),"",DATEDIF(IF(ISNUMBER(H51),H51,DATEVALUE(H51)),DATE(VALUE(RIGHT('INPUT DATA'!$F$18,4)),5,31),"YM")),"") | M51: M
B52: 38 | C52: =IF('INPUT DATA'!L47="","",'INPUT DATA'!L47) | F52: =IF('INPUT DATA'!M47="","",'INPUT DATA'!M47) | H52: =IF('INPUT DATA'!N47="","",'INPUT DATA'!N47) | I52: =IFERROR(IF(OR(H52="",H52=0),"",DATEDIF(IF(ISNUMBER(H52),H52,DATEVALUE(H52)),DATE(VALUE(LEFT('INPUT DATA'!$F$18,4)),6,1),"Y")),"") | J52: =IFERROR(IF(OR(H52="",H52=0),"",DATEDIF(IF(ISNUMBER(H52),H52,DATEVALUE(H52)),DATE(VALUE(LEFT('INPUT DATA'!$F$18,4)),6,1),"YM")),"") | K52: =IFERROR(IF(OR(H52="",H52=0),"",DATEDIF(IF(ISNUMBER(H52),H52,DATEVALUE(H52)),DATE(VALUE(RIGHT('INPUT DATA'!$F$18,4)),5,31),"Y")),"") | L52: =IFERROR(IF(OR(H52="",H52=0),"",DATEDIF(IF(ISNUMBER(H52),H52,DATEVALUE(H52)),DATE(VALUE(RIGHT('INPUT DATA'!$F$18,4)),5,31),"YM")),"") | M52: M
B53: 39 | C53: =IF('INPUT DATA'!L48="","",'INPUT DATA'!L48) | F53: =IF('INPUT DATA'!M48="","",'INPUT DATA'!M48) | H53: =IF('INPUT DATA'!N48="","",'INPUT DATA'!N48) | I53: =IFERROR(IF(OR(H53="",H53=0),"",DATEDIF(IF(ISNUMBER(H53),H53,DATEVALUE(H53)),DATE(VALUE(LEFT('INPUT DATA'!$F$18,4)),6,1),"Y")),"") | J53: =IFERROR(IF(OR(H53="",H53=0),"",DATEDIF(IF(ISNUMBER(H53),H53,DATEVALUE(H53)),DATE(VALUE(LEFT('INPUT DATA'!$F$18,4)),6,1),"YM")),"") | K53: =IFERROR(IF(OR(H53="",H53=0),"",DATEDIF(IF(ISNUMBER(H53),H53,DATEVALUE(H53)),DATE(VALUE(RIGHT('INPUT DATA'!$F$18,4)),5,31),"Y")),"") | L53: =IFERROR(IF(OR(H53="",H53=0),"",DATEDIF(IF(ISNUMBER(H53),H53,DATEVALUE(H53)),DATE(VALUE(RIGHT('INPUT DATA'!$F$18,4)),5,31),"YM")),"") | M53: M
B54: 40 | C54: =IF('INPUT DATA'!L49="","",'INPUT DATA'!L49) | F54: =IF('INPUT DATA'!M49="","",'INPUT DATA'!M49) | H54: =IF('INPUT DATA'!N49="","",'INPUT DATA'!N49) | I54: =IFERROR(IF(OR(H54="",H54=0),"",DATEDIF(IF(ISNUMBER(H54),H54,DATEVALUE(H54)),DATE(VALUE(LEFT('INPUT DATA'!$F$18,4)),6,1),"Y")),"") | J54: =IFERROR(IF(OR(H54="",H54=0),"",DATEDIF(IF(ISNUMBER(H54),H54,DATEVALUE(H54)),DATE(VALUE(LEFT('INPUT DATA'!$F$18,4)),6,1),"YM")),"") | K54: =IFERROR(IF(OR(H54="",H54=0),"",DATEDIF(IF(ISNUMBER(H54),H54,DATEVALUE(H54)),DATE(VALUE(RIGHT('INPUT DATA'!$F$18,4)),5,31),"Y")),"") | L54: =IFERROR(IF(OR(H54="",H54=0),"",DATEDIF(IF(ISNUMBER(H54),H54,DATEVALUE(H54)),DATE(VALUE(RIGHT('INPUT DATA'!$F$18,4)),5,31),"YM")),"") | M54: M
B55: 41 | C55: =IF('INPUT DATA'!L50="","",'INPUT DATA'!L50) | F55: =IF('INPUT DATA'!M50="","",'INPUT DATA'!M50) | H55: =IF('INPUT DATA'!N50="","",'INPUT DATA'!N50) | I55: =IFERROR(IF(OR(H55="",H55=0),"",DATEDIF(IF(ISNUMBER(H55),H55,DATEVALUE(H55)),DATE(VALUE(LEFT('INPUT DATA'!$F$18,4)),6,1),"Y")),"") | J55: =IFERROR(IF(OR(H55="",H55=0),"",DATEDIF(IF(ISNUMBER(H55),H55,DATEVALUE(H55)),DATE(VALUE(LEFT('INPUT DATA'!$F$18,4)),6,1),"YM")),"") | K55: =IFERROR(IF(OR(H55="",H55=0),"",DATEDIF(IF(ISNUMBER(H55),H55,DATEVALUE(H55)),DATE(VALUE(RIGHT('INPUT DATA'!$F$18,4)),5,31),"Y")),"") | L55: =IFERROR(IF(OR(H55="",H55=0),"",DATEDIF(IF(ISNUMBER(H55),H55,DATEVALUE(H55)),DATE(VALUE(RIGHT('INPUT DATA'!$F$18,4)),5,31),"YM")),"") | M55: M
B56: 42 | C56: =IF('INPUT DATA'!L51="","",'INPUT DATA'!L51) | F56: =IF('INPUT DATA'!M51="","",'INPUT DATA'!M51) | H56: =IF('INPUT DATA'!N51="","",'INPUT DATA'!N51) | I56: =IFERROR(IF(OR(H56="",H56=0),"",DATEDIF(IF(ISNUMBER(H56),H56,DATEVALUE(H56)),DATE(VALUE(LEFT('INPUT DATA'!$F$18,4)),6,1),"Y")),"") | J56: =IFERROR(IF(OR(H56="",H56=0),"",DATEDIF(IF(ISNUMBER(H56),H56,DATEVALUE(H56)),DATE(VALUE(LEFT('INPUT DATA'!$F$18,4)),6,1),"YM")),"") | K56: =IFERROR(IF(OR(H56="",H56=0),"",DATEDIF(IF(ISNUMBER(H56),H56,DATEVALUE(H56)),DATE(VALUE(RIGHT('INPUT DATA'!$F$18,4)),5,31),"Y")),"") | L56: =IFERROR(IF(OR(H56="",H56=0),"",DATEDIF(IF(ISNUMBER(H56),H56,DATEVALUE(H56)),DATE(VALUE(RIGHT('INPUT DATA'!$F$18,4)),5,31),"YM")),"") | M56: M
B57: 43 | C57: =IF('INPUT DATA'!L52="","",'INPUT DATA'!L52) | F57: =IF('INPUT DATA'!M52="","",'INPUT DATA'!M52) | H57: =IF('INPUT DATA'!N52="","",'INPUT DATA'!N52) | I57: =IFERROR(IF(OR(H57="",H57=0),"",DATEDIF(IF(ISNUMBER(H57),H57,DATEVALUE(H57)),DATE(VALUE(LEFT('INPUT DATA'!$F$18,4)),6,1),"Y")),"") | J57: =IFERROR(IF(OR(H57="",H57=0),"",DATEDIF(IF(ISNUMBER(H57),H57,DATEVALUE(H57)),DATE(VALUE(LEFT('INPUT DATA'!$F$18,4)),6,1),"YM")),"") | K57: =IFERROR(IF(OR(H57="",H57=0),"",DATEDIF(IF(ISNUMBER(H57),H57,DATEVALUE(H57)),DATE(VALUE(RIGHT('INPUT DATA'!$F$18,4)),5,31),"Y")),"") | L57: =IFERROR(IF(OR(H57="",H57=0),"",DATEDIF(IF(ISNUMBER(H57),H57,DATEVALUE(H57)),DATE(VALUE(RIGHT('INPUT DATA'!$F$18,4)),5,31),"YM")),"") | M57: M
B58: 44 | C58: =IF('INPUT DATA'!L53="","",'INPUT DATA'!L53) | F58: =IF('INPUT DATA'!M53="","",'INPUT DATA'!M53) | H58: =IF('INPUT DATA'!N53="","",'INPUT DATA'!N53) | I58: =IFERROR(IF(OR(H58="",H58=0),"",DATEDIF(IF(ISNUMBER(H58),H58,DATEVALUE(H58)),DATE(VALUE(LEFT('INPUT DATA'!$F$18,4)),6,1),"Y")),"") | J58: =IFERROR(IF(OR(H58="",H58=0),"",DATEDIF(IF(ISNUMBER(H58),H58,DATEVALUE(H58)),DATE(VALUE(LEFT('INPUT DATA'!$F$18,4)),6,1),"YM")),"") | K58: =IFERROR(IF(OR(H58="",H58=0),"",DATEDIF(IF(ISNUMBER(H58),H58,DATEVALUE(H58)),DATE(VALUE(RIGHT('INPUT DATA'!$F$18,4)),5,31),"Y")),"") | L58: =IFERROR(IF(OR(H58="",H58=0),"",DATEDIF(IF(ISNUMBER(H58),H58,DATEVALUE(H58)),DATE(VALUE(RIGHT('INPUT DATA'!$F$18,4)),5,31),"YM")),"") | M58: M
B59: 45 | C59: =IF('INPUT DATA'!L54="","",'INPUT DATA'!L54) | F59: =IF('INPUT DATA'!M54="","",'INPUT DATA'!M54) | H59: =IF('INPUT DATA'!N54="","",'INPUT DATA'!N54) | I59: =IFERROR(IF(OR(H59="",H59=0),"",DATEDIF(IF(ISNUMBER(H59),H59,DATEVALUE(H59)),DATE(VALUE(LEFT('INPUT DATA'!$F$18,4)),6,1),"Y")),"") | J59: =IFERROR(IF(OR(H59="",H59=0),"",DATEDIF(IF(ISNUMBER(H59),H59,DATEVALUE(H59)),DATE(VALUE(LEFT('INPUT DATA'!$F$18,4)),6,1),"YM")),"") | K59: =IFERROR(IF(OR(H59="",H59=0),"",DATEDIF(IF(ISNUMBER(H59),H59,DATEVALUE(H59)),DATE(VALUE(RIGHT('INPUT DATA'!$F$18,4)),5,31),"Y")),"") | L59: =IFERROR(IF(OR(H59="",H59=0),"",DATEDIF(IF(ISNUMBER(H59),H59,DATEVALUE(H59)),DATE(VALUE(RIGHT('INPUT DATA'!$F$18,4)),5,31),"YM")),"") | M59: M
B60: 46 | C60: =IF('INPUT DATA'!L55="","",'INPUT DATA'!L55) | F60: =IF('INPUT DATA'!M55="","",'INPUT DATA'!M55) | H60: =IF('INPUT DATA'!N55="","",'INPUT DATA'!N55) | I60: =IFERROR(IF(OR(H60="",H60=0),"",DATEDIF(IF(ISNUMBER(H60),H60,DATEVALUE(H60)),DATE(VALUE(LEFT('INPUT DATA'!$F$18,4)),6,1),"Y")),"") | J60: =IFERROR(IF(OR(H60="",H60=0),"",DATEDIF(IF(ISNUMBER(H60),H60,DATEVALUE(H60)),DATE(VALUE(LEFT('INPUT DATA'!$F$18,4)),6,1),"YM")),"") | K60: =IFERROR(IF(OR(H60="",H60=0),"",DATEDIF(IF(ISNUMBER(H60),H60,DATEVALUE(H60)),DATE(VALUE(RIGHT('INPUT DATA'!$F$18,4)),5,31),"Y")),"") | L60: =IFERROR(IF(OR(H60="",H60=0),"",DATEDIF(IF(ISNUMBER(H60),H60,DATEVALUE(H60)),DATE(VALUE(RIGHT('INPUT DATA'!$F$18,4)),5,31),"YM")),"") | M60: M
B61: 47 | C61: =IF('INPUT DATA'!L56="","",'INPUT DATA'!L56) | F61: =IF('INPUT DATA'!M56="","",'INPUT DATA'!M56) | H61: =IF('INPUT DATA'!N56="","",'INPUT DATA'!N56) | I61: =IFERROR(IF(OR(H61="",H61=0),"",DATEDIF(IF(ISNUMBER(H61),H61,DATEVALUE(H61)),DATE(VALUE(LEFT('INPUT DATA'!$F$18,4)),6,1),"Y")),"") | J61: =IFERROR(IF(OR(H61="",H61=0),"",DATEDIF(IF(ISNUMBER(H61),H61,DATEVALUE(H61)),DATE(VALUE(LEFT('INPUT DATA'!$F$18,4)),6,1),"YM")),"") | K61: =IFERROR(IF(OR(H61="",H61=0),"",DATEDIF(IF(ISNUMBER(H61),H61,DATEVALUE(H61)),DATE(VALUE(RIGHT('INPUT DATA'!$F$18,4)),5,31),"Y")),"") | L61: =IFERROR(IF(OR(H61="",H61=0),"",DATEDIF(IF(ISNUMBER(H61),H61,DATEVALUE(H61)),DATE(VALUE(RIGHT('INPUT DATA'!$F$18,4)),5,31),"YM")),"") | M61: M
B62: 48 | C62: =IF('INPUT DATA'!L57="","",'INPUT DATA'!L57) | F62: =IF('INPUT DATA'!M57="","",'INPUT DATA'!M57) | H62: =IF('INPUT DATA'!N57="","",'INPUT DATA'!N57) | I62: =IFERROR(IF(OR(H62="",H62=0),"",DATEDIF(IF(ISNUMBER(H62),H62,DATEVALUE(H62)),DATE(VALUE(LEFT('INPUT DATA'!$F$18,4)),6,1),"Y")),"") | J62: =IFERROR(IF(OR(H62="",H62=0),"",DATEDIF(IF(ISNUMBER(H62),H62,DATEVALUE(H62)),DATE(VALUE(LEFT('INPUT DATA'!$F$18,4)),6,1),"YM")),"") | K62: =IFERROR(IF(OR(H62="",H62=0),"",DATEDIF(IF(ISNUMBER(H62),H62,DATEVALUE(H62)),DATE(VALUE(RIGHT('INPUT DATA'!$F$18,4)),5,31),"Y")),"") | L62: =IFERROR(IF(OR(H62="",H62=0),"",DATEDIF(IF(ISNUMBER(H62),H62,DATEVALUE(H62)),DATE(VALUE(RIGHT('INPUT DATA'!$F$18,4)),5,31),"YM")),"") | M62: M
... B64: 50 | C64: =IF('INPUT DATA'!L59="","",'INPUT DATA'!L59) | F64: =IF('INPUT DATA'!M59="","",'INPUT DATA'!M59) | H64: =IF('INPUT DATA'!N59="","",'INPUT DATA'!N59) | I64: =IFERROR(IF(OR(H64="",H64=0),"",DATEDIF(IF(ISNUMBER(H64),H64,DATEVALUE(H64)),DATE(VALUE(LEFT('INPUT DATA'!$F$18,4)),6,1),"Y")),"") | J64: =IFERROR(IF(OR(H64="",H64=0),"",DATEDIF(IF(ISNUMBER(H64),H64,DATEVALUE(H64)),DATE(VALUE(LEFT('INPUT DATA'!$F$18,4)),6,1),"YM")),"") | K64: =IFERROR(IF(OR(H64="",H64=0),"",DATEDIF(IF(ISNUMBER(H64),H64,DATEVALUE(H64)),DATE(VALUE(RIGHT('INPUT DATA'!$F$18,4)),5,31),"Y")),"") | L64: =IFERROR(IF(OR(H64="",H64=0),"",DATEDIF(IF(ISNUMBER(H64),H64,DATEVALUE(H64)),DATE(VALUE(RIGHT('INPUT DATA'!$F$18,4)),5,31),"YM")),"") | M64: M
B65: FEMALE
B66: 1 | C66: =IF('INPUT DATA'!Q11="","",'INPUT DATA'!Q11) | F66: =IF('INPUT DATA'!R11="","",'INPUT DATA'!R11) | H66: =IF('INPUT DATA'!S11="","",'INPUT DATA'!S11) | I66: =IFERROR(IF(OR(H66="",H66=0),"",DATEDIF(IF(ISNUMBER(H66),H66,DATEVALUE(H66)),DATE(VALUE(LEFT('INPUT DATA'!$F$18,4)),6,1),"Y")),"") | J66: =IFERROR(IF(OR(H66="",H66=0),"",DATEDIF(IF(ISNUMBER(H66),H66,DATEVALUE(H66)),DATE(VALUE(LEFT('INPUT DATA'!$F$18,4)),6,1),"YM")),"") | K66: =IFERROR(IF(OR(H66="",H66=0),"",DATEDIF(IF(ISNUMBER(H66),H66,DATEVALUE(H66)),DATE(VALUE(RIGHT('INPUT DATA'!$F$18,4)),5,31),"Y")),"") | L66: =IFERROR(IF(OR(H66="",H66=0),"",DATEDIF(IF(ISNUMBER(H66),H66,DATEVALUE(H66)),DATE(VALUE(RIGHT('INPUT DATA'!$F$18,4)),5,31),"YM")),"") | M66: F
B67: 2 | C67: =IF('INPUT DATA'!Q12="","",'INPUT DATA'!Q12) | F67: =IF('INPUT DATA'!R12="","",'INPUT DATA'!R12) | H67: =IF('INPUT DATA'!S12="","",'INPUT DATA'!S12) | I67: =IFERROR(IF(OR(H67="",H67=0),"",DATEDIF(IF(ISNUMBER(H67),H67,DATEVALUE(H67)),DATE(VALUE(LEFT('INPUT DATA'!$F$18,4)),6,1),"Y")),"") | J67: =IFERROR(IF(OR(H67="",H67=0),"",DATEDIF(IF(ISNUMBER(H67),H67,DATEVALUE(H67)),DATE(VALUE(LEFT('INPUT DATA'!$F$18,4)),6,1),"YM")),"") | K67: =IFERROR(IF(OR(H67="",H67=0),"",DATEDIF(IF(ISNUMBER(H67),H67,DATEVALUE(H67)),DATE(VALUE(RIGHT('INPUT DATA'!$F$18,4)),5,31),"Y")),"") | L67: =IFERROR(IF(OR(H67="",H67=0),"",DATEDIF(IF(ISNUMBER(H67),H67,DATEVALUE(H67)),DATE(VALUE(RIGHT('INPUT DATA'!$F$18,4)),5,31),"YM")),"") | M67: F
B68: 3 | C68: =IF('INPUT DATA'!Q13="","",'INPUT DATA'!Q13) | F68: =IF('INPUT DATA'!R13="","",'INPUT DATA'!R13) | H68: =IF('INPUT DATA'!S13="","",'INPUT DATA'!S13) | I68: =IFERROR(IF(OR(H68="",H68=0),"",DATEDIF(IF(ISNUMBER(H68),H68,DATEVALUE(H68)),DATE(VALUE(LEFT('INPUT DATA'!$F$18,4)),6,1),"Y")),"") | J68: =IFERROR(IF(OR(H68="",H68=0),"",DATEDIF(IF(ISNUMBER(H68),H68,DATEVALUE(H68)),DATE(VALUE(LEFT('INPUT DATA'!$F$18,4)),6,1),"YM")),"") | K68: =IFERROR(IF(OR(H68="",H68=0),"",DATEDIF(IF(ISNUMBER(H68),H68,DATEVALUE(H68)),DATE(VALUE(RIGHT('INPUT DATA'!$F$18,4)),5,31),"Y")),"") | L68: =IFERROR(IF(OR(H68="",H68=0),"",DATEDIF(IF(ISNUMBER(H68),H68,DATEVALUE(H68)),DATE(VALUE(RIGHT('INPUT DATA'!$F$18,4)),5,31),"YM")),"") | M68: F
...

Sheet TERM 3 SUMMARY
A1: CLASS SUMMARY - THIRD
D5: REGION | E5: ='INPUT DATA'!F10 -> 0 | I5: DIVISION | K5: ='INPUT DATA'!F11 -> 0
D6: SCHOOL NAME | E6: ='INPUT DATA'!F16 -> 0 | I6: SCHOOL ID | K6: ='INPUT DATA'!F15 -> 0 | S6: SCHOOL YEAR | T6: ='INPUT DATA'!F18 -> 0
B9: THIRD TERM | I9: Age (BoSY) | K9: Age (EoSY) | M9: Sex | N9: GRADE LEVEL | R9: ='INPUT DATA'!F27 -> 0 | AE9: ADVISER | AH9: ='INPUT DATA'!F26 -> 0
N10: SECTION | R10: ='INPUT DATA'!F28 -> 0
N11: I. Sensory Perceptual and Motor Development | S11: II. Socio-emotional Development | Z11: III. Cognitive Development | AT11: IV. Language, Literacy, and Communication Development
B12: LEARNERS' NAMES | F12: LRN | H12: Date of Birth | I12: Years | J12: Months | K12: Years | L12: Months | N12: 1 | O12: 2 | P12: 3 | Q12: 4 | R12: 5 | S12: 1 | T12: 2 | U12: 3 | V12: 4 | W12: 5 | X12: 6 | Y12: 7 | Z12: 1 | AA12: 2 | AB12: 3 | AC12: 4 | AD12: 5 | AE12: 6 | AF12: 7 | AG12: 8 | AH12: 9 | AI12: 10 | AJ12: 11 | AK12: 12 | AL12: 13 | AM12: 14 | AN12: 15 | AO12: 16 | AP12: 17 | AQ12: 18 | AR12: 19 | AS12: 20 | AT12: A. Listening and Viewing | AX12: B. Sight Word Recognition | AZ12: C. Speaking | BF12: D. Reading | BL12: E. Comprehension | BN12: F. Concepts of Print | BQ12: G. Writing
AT13: 1 | AU13: 2 | AV13: 3 | AW13: 4 | AX13: 5 | AY13: 6 | AZ13: 7 | BA13: 8 | BB13: 9 | BC13: 10 | BD13: 11 | BE13: 12 | BF13: Phonological / Phonemic Awareness | BG13: Letter Knowledge | BJ13: Letter Sound Relationship | BL13: 19 | BM13: 20 | BN13: 21 | BO13: 22 | BP13: 23 | BQ13: 24 | BR13: 25 | BS13: 26 | BT13: 27 | BU13: 28
BF14: 13 | BG14: 14 | BH14: 15 | BI14: 16 | BJ14: 17 | BK14: 18
B15: MALE
B16: 1 | C16: =IF('INPUT DATA'!L11="","",'INPUT DATA'!L11) | F16: =IF('INPUT DATA'!M11="","",'INPUT DATA'!M11) | H16: =IF('INPUT DATA'!N11="","",'INPUT DATA'!N11) | I16: =IF(H16="","",DATEDIF(H16,DATE(2026,6,8),"Y")) | J16: =IF(H16="","",DATEDIF(H16,DATE(2026,6,8),"YM")) | K16: =IF(H16="","",DATEDIF(H16,DATE(2027,4,8),"Y")) | L16: =IF(H16="","",DATEDIF(H16,DATE(2027,4,8),"YM")) | M16: M
B17: 2 | C17: =IF('INPUT DATA'!L12="","",'INPUT DATA'!L12) | F17: =IF('INPUT DATA'!M12="","",'INPUT DATA'!M12) | H17: =IF('INPUT DATA'!N12="","",'INPUT DATA'!N12) | I17: =IF(H17="","",DATEDIF(H17,DATE(2026,6,8),"Y")) | J17: =IF(H17="","",DATEDIF(H17,DATE(2026,6,8),"YM")) | K17: =IF(H17="","",DATEDIF(H17,DATE(2027,4,8),"Y")) | L17: =IF(H17="","",DATEDIF(H17,DATE(2027,4,8),"YM")) | M17: M
B18: 3 | C18: =IF('INPUT DATA'!L13="","",'INPUT DATA'!L13) | F18: =IF('INPUT DATA'!M13="","",'INPUT DATA'!M13) | H18: =IF('INPUT DATA'!N13="","",'INPUT DATA'!N13) | I18: =IF(H18="","",DATEDIF(H18,DATE(2026,6,8),"Y")) | J18: =IF(H18="","",DATEDIF(H18,DATE(2026,6,8),"YM")) | K18: =IF(H18="","",DATEDIF(H18,DATE(2027,4,8),"Y")) | L18: =IF(H18="","",DATEDIF(H18,DATE(2027,4,8),"YM")) | M18: M
B19: 4 | C19: =IF('INPUT DATA'!L14="","",'INPUT DATA'!L14) | F19: =IF('INPUT DATA'!M14="","",'INPUT DATA'!M14) | H19: =IF('INPUT DATA'!N14="","",'INPUT DATA'!N14) | I19: =IF(H19="","",DATEDIF(H19,DATE(2026,6,8),"Y")) | J19: =IF(H19="","",DATEDIF(H19,DATE(2026,6,8),"YM")) | K19: =IF(H19="","",DATEDIF(H19,DATE(2027,4,8),"Y")) | L19: =IF(H19="","",DATEDIF(H19,DATE(2027,4,8),"YM")) | M19: M
B20: 5 | C20: =IF('INPUT DATA'!L15="","",'INPUT DATA'!L15) | F20: =IF('INPUT DATA'!M15="","",'INPUT DATA'!M15) | H20: =IF('INPUT DATA'!N15="","",'INPUT DATA'!N15) | I20: =IF(H20="","",DATEDIF(H20,DATE(2026,6,8),"Y")) | J20: =IF(H20="","",DATEDIF(H20,DATE(2026,6,8),"YM")) | K20: =IF(H20="","",DATEDIF(H20,DATE(2027,4,8),"Y")) | L20: =IF(H20="","",DATEDIF(H20,DATE(2027,4,8),"YM")) | M20: M
B21: 6 | C21: =IF('INPUT DATA'!L16="","",'INPUT DATA'!L16) | F21: =IF('INPUT DATA'!M16="","",'INPUT DATA'!M16) | H21: =IF('INPUT DATA'!N16="","",'INPUT DATA'!N16) | I21: =IF(H21="","",DATEDIF(H21,DATE(2026,6,8),"Y")) | J21: =IF(H21="","",DATEDIF(H21,DATE(2026,6,8),"YM")) | K21: =IF(H21="","",DATEDIF(H21,DATE(2027,4,8),"Y")) | L21: =IF(H21="","",DATEDIF(H21,DATE(2027,4,8),"YM")) | M21: M
B22: 7 | C22: =IF('INPUT DATA'!L17="","",'INPUT DATA'!L17) | F22: =IF('INPUT DATA'!M17="","",'INPUT DATA'!M17) | H22: =IF('INPUT DATA'!N17="","",'INPUT DATA'!N17) | I22: =IF(H22="","",DATEDIF(H22,DATE(2026,6,8),"Y")) | J22: =IF(H22="","",DATEDIF(H22,DATE(2026,6,8),"YM")) | K22: =IF(H22="","",DATEDIF(H22,DATE(2027,4,8),"Y")) | L22: =IF(H22="","",DATEDIF(H22,DATE(2027,4,8),"YM")) | M22: M
B23: 8 | C23: =IF('INPUT DATA'!L18="","",'INPUT DATA'!L18) | F23: =IF('INPUT DATA'!M18="","",'INPUT DATA'!M18) | H23: =IF('INPUT DATA'!N18="","",'INPUT DATA'!N18) | I23: =IF(H23="","",DATEDIF(H23,DATE(2026,6,8),"Y")) | J23: =IF(H23="","",DATEDIF(H23,DATE(2026,6,8),"YM")) | K23: =IF(H23="","",DATEDIF(H23,DATE(2027,4,8),"Y")) | L23: =IF(H23="","",DATEDIF(H23,DATE(2027,4,8),"YM")) | M23: M
B24: 9 | C24: =IF('INPUT DATA'!L19="","",'INPUT DATA'!L19) | F24: =IF('INPUT DATA'!M19="","",'INPUT DATA'!M19) | H24: =IF('INPUT DATA'!N19="","",'INPUT DATA'!N19) | I24: =IF(H24="","",DATEDIF(H24,DATE(2026,6,8),"Y")) | J24: =IF(H24="","",DATEDIF(H24,DATE(2026,6,8),"YM")) | K24: =IF(H24="","",DATEDIF(H24,DATE(2027,4,8),"Y")) | L24: =IF(H24="","",DATEDIF(H24,DATE(2027,4,8),"YM")) | M24: M
B25: 10 | C25: =IF('INPUT DATA'!L20="","",'INPUT DATA'!L20) | F25: =IF('INPUT DATA'!M20="","",'INPUT DATA'!M20) | H25: =IF('INPUT DATA'!N20="","",'INPUT DATA'!N20) | I25: =IF(H25="","",DATEDIF(H25,DATE(2026,6,8),"Y")) | J25: =IF(H25="","",DATEDIF(H25,DATE(2026,6,8),"YM")) | K25: =IF(H25="","",DATEDIF(H25,DATE(2027,4,8),"Y")) | L25: =IF(H25="","",DATEDIF(H25,DATE(2027,4,8),"YM")) | M25: M
B26: 11 | C26: =IF('INPUT DATA'!L21="","",'INPUT DATA'!L21) | F26: =IF('INPUT DATA'!M21="","",'INPUT DATA'!M21) | H26: =IF('INPUT DATA'!N21="","",'INPUT DATA'!N21) | I26: =IF(H26="","",DATEDIF(H26,DATE(2026,6,8),"Y")) | J26: =IF(H26="","",DATEDIF(H26,DATE(2026,6,8),"YM")) | K26: =IF(H26="","",DATEDIF(H26,DATE(2027,4,8),"Y")) | L26: =IF(H26="","",DATEDIF(H26,DATE(2027,4,8),"YM")) | M26: M
B27: 12 | C27: =IF('INPUT DATA'!L22="","",'INPUT DATA'!L22) | F27: =IF('INPUT DATA'!M22="","",'INPUT DATA'!M22) | H27: =IF('INPUT DATA'!N22="","",'INPUT DATA'!N22) | I27: =IF(H27="","",DATEDIF(H27,DATE(2026,6,8),"Y")) | J27: =IF(H27="","",DATEDIF(H27,DATE(2026,6,8),"YM")) | K27: =IF(H27="","",DATEDIF(H27,DATE(2027,4,8),"Y")) | L27: =IF(H27="","",DATEDIF(H27,DATE(2027,4,8),"YM")) | M27: M
... B64: 50 | C64: =IF('INPUT DATA'!L59="","",'INPUT DATA'!L59) | F64: =IF('INPUT DATA'!M59="","",'INPUT DATA'!M59) | H64: =IF('INPUT DATA'!N59="","",'INPUT DATA'!N59) | I64: =IF(H64="","",DATEDIF(H64,DATE(2026,6,8),"Y")) | J64: =IF(H64="","",DATEDIF(H64,DATE(2026,6,8),"YM")) | K64: =IF(H64="","",DATEDIF(H64,DATE(2027,4,8),"Y")) | L64: =IF(H64="","",DATEDIF(H64,DATE(2027,4,8),"YM")) | M64: M
B65: FEMALE
B66: 1 | C66: =IF('INPUT DATA'!Q11="","",'INPUT DATA'!Q11) | F66: =IF('INPUT DATA'!R11="","",'INPUT DATA'!R11) | H66: =IF('INPUT DATA'!S11="","",'INPUT DATA'!S11) | I66: =IF(H66="","",DATEDIF(H66,DATE(2026,6,8),"Y")) | J66: =IF(H66="","",DATEDIF(H66,DATE(2026,6,8),"YM")) | K66: =IF(H66="","",DATEDIF(H66,DATE(2027,4,8),"Y")) | L66: =IF(H66="","",DATEDIF(H66,DATE(2027,4,8),"YM")) | M66: F
B67: 2 | C67: =IF('INPUT DATA'!Q12="","",'INPUT DATA'!Q12) | F67: =IF('INPUT DATA'!R12="","",'INPUT DATA'!R12) | H67: =IF('INPUT DATA'!S12="","",'INPUT DATA'!S12) | I67: =IF(H67="","",DATEDIF(H67,DATE(2026,6,8),"Y")) | J67: =IF(H67="","",DATEDIF(H67,DATE(2026,6,8),"YM")) | K67: =IF(H67="","",DATEDIF(H67,DATE(2027,4,8),"Y")) | L67: =IF(H67="","",DATEDIF(H67,DATE(2027,4,8),"YM")) | M67: F
B68: 3 | C68: =IF('INPUT DATA'!Q13="","",'INPUT DATA'!Q13) | F68: =IF('INPUT DATA'!R13="","",'INPUT DATA'!R13) | H68: =IF('INPUT DATA'!S13="","",'INPUT DATA'!S13) | I68: =IF(H68="","",DATEDIF(H68,DATE(2026,6,8),"Y")) | J68: =IF(H68="","",DATEDIF(H68,DATE(2026,6,8),"YM")) | K68: =IF(H68="","",DATEDIF(H68,DATE(2027,4,8),"Y")) | L68: =IF(H68="","",DATEDIF(H68,DATE(2027,4,8),"YM")) | M68: F
B69: 4 | C69: =IF('INPUT DATA'!Q14="","",'INPUT DATA'!Q14) | F69: =IF('INPUT DATA'!R14="","",'INPUT DATA'!R14) | H69: =IF('INPUT DATA'!S14="","",'INPUT DATA'!S14) | I69: =IF(H69="","",DATEDIF(H69,DATE(2026,6,8),"Y")) | J69: =IF(H69="","",DATEDIF(H69,DATE(2026,6,8),"YM")) | K69: =IF(H69="","",DATEDIF(H69,DATE(2027,4,8),"Y")) | L69: =IF(H69="","",DATEDIF(H69,DATE(2027,4,8),"YM")) | M69: F
B70: 5 | C70: =IF('INPUT DATA'!Q15="","",'INPUT DATA'!Q15) | F70: =IF('INPUT DATA'!R15="","",'INPUT DATA'!R15) | H70: =IF('INPUT DATA'!S15="","",'INPUT DATA'!S15) | I70: =IF(H70="","",DATEDIF(H70,DATE(2026,6,8),"Y")) | J70: =IF(H70="","",DATEDIF(H70,DATE(2026,6,8),"YM")) | K70: =IF(H70="","",DATEDIF(H70,DATE(2027,4,8),"Y")) | L70: =IF(H70="","",DATEDIF(H70,DATE(2027,4,8),"YM")) | M70: F
B71: 6 | C71: =IF('INPUT DATA'!Q16="","",'INPUT DATA'!Q16) | F71: =IF('INPUT DATA'!R16="","",'INPUT DATA'!R16) | H71: =IF('INPUT DATA'!S16="","",'INPUT DATA'!S16) | I71: =IF(H71="","",DATEDIF(H71,DATE(2026,6,8),"Y")) | J71: =IF(H71="","",DATEDIF(H71,DATE(2026,6,8),"YM")) | K71: =IF(H71="","",DATEDIF(H71,DATE(2027,4,8),"Y")) | L71: =IF(H71="","",DATEDIF(H71,DATE(2027,4,8),"YM")) | M71: F
B72: 7 | C72: =IF('INPUT DATA'!Q17="","",'INPUT DATA'!Q17) | F72: =IF('INPUT DATA'!R17="","",'INPUT DATA'!R17) | H72: =IF('INPUT DATA'!S17="","",'INPUT DATA'!S17) | I72: =IF(H72="","",DATEDIF(H72,DATE(2026,6,8),"Y")) | J72: =IF(H72="","",DATEDIF(H72,DATE(2026,6,8),"YM")) | K72: =IF(H72="","",DATEDIF(H72,DATE(2027,4,8),"Y")) | L72: =IF(H72="","",DATEDIF(H72,DATE(2027,4,8),"YM")) | M72: F
B73: 8 | C73: =IF('INPUT DATA'!Q18="","",'INPUT DATA'!Q18) | F73: =IF('INPUT DATA'!R18="","",'INPUT DATA'!R18) | H73: =IF('INPUT DATA'!S18="","",'INPUT DATA'!S18) | I73: =IF(H73="","",DATEDIF(H73,DATE(2026,6,8),"Y")) | J73: =IF(H73="","",DATEDIF(H73,DATE(2026,6,8),"YM")) | K73: =IF(H73="","",DATEDIF(H73,DATE(2027,4,8),"Y")) | L73: =IF(H73="","",DATEDIF(H73,DATE(2027,4,8),"YM")) | M73: F
B74: 9 | C74: =IF('INPUT DATA'!Q19="","",'INPUT DATA'!Q19) | F74: =IF('INPUT DATA'!R19="","",'INPUT DATA'!R19) | H74: =IF('INPUT DATA'!S19="","",'INPUT DATA'!S19) | I74: =IF(H74="","",DATEDIF(H74,DATE(2026,6,8),"Y")) | J74: =IF(H74="","",DATEDIF(H74,DATE(2026,6,8),"YM")) | K74: =IF(H74="","",DATEDIF(H74,DATE(2027,4,8),"Y")) | L74: =IF(H74="","",DATEDIF(H74,DATE(2027,4,8),"YM")) | M74: F
B75: 10 | C75: =IF('INPUT DATA'!Q20="","",'INPUT DATA'!Q20) | F75: =IF('INPUT DATA'!R20="","",'INPUT DATA'!R20) | H75: =IF('INPUT DATA'!S20="","",'INPUT DATA'!S20) | I75: =IF(H75="","",DATEDIF(H75,DATE(2026,6,8),"Y")) | J75: =IF(H75="","",DATEDIF(H75,DATE(2026,6,8),"YM")) | K75: =IF(H75="","",DATEDIF(H75,DATE(2027,4,8),"Y")) | L75: =IF(H75="","",DATEDIF(H75,DATE(2027,4,8),"YM")) | M75: F
B76: 11 | C76: =IF('INPUT DATA'!Q21="","",'INPUT DATA'!Q21) | F76: =IF('INPUT DATA'!R21="","",'INPUT DATA'!R21) | H76: =IF('INPUT DATA'!S21="","",'INPUT DATA'!S21) | I76: =IF(H76="","",DATEDIF(H76,DATE(2026,6,8),"Y")) | J76: =IF(H76="","",DATEDIF(H76,DATE(2026,6,8),"YM")) | K76: =IF(H76="","",DATEDIF(H76,DATE(2027,4,8),"Y")) | L76: =IF(H76="","",DATEDIF(H76,DATE(2027,4,8),"YM")) | M76: F
B77: 12 | C77: =IF('INPUT DATA'!Q22="","",'INPUT DATA'!Q22) | F77: =IF('INPUT DATA'!R22="","",'INPUT DATA'!R22) | H77: =IF('INPUT DATA'!S22="","",'INPUT DATA'!S22) | I77: =IF(H77="","",DATEDIF(H77,DATE(2026,6,8),"Y")) | J77: =IF(H77="","",DATEDIF(H77,DATE(2026,6,8),"YM")) | K77: =IF(H77="","",DATEDIF(H77,DATE(2027,4,8),"Y")) | L77: =IF(H77="","",DATEDIF(H77,DATE(2027,4,8),"YM")) | M77: F
... B114: 50 | C114: =IF('INPUT DATA'!Q59="","",'INPUT DATA'!Q59) | F114: =IF('INPUT DATA'!R59="","",'INPUT DATA'!R59) | H114: =IF('INPUT DATA'!S59="","",'INPUT DATA'!S59) | I114: =IF(H114="","",DATEDIF(H114,DATE(2026,6,8),"Y")) | J114: =IF(H114="","",DATEDIF(H114,DATE(2026,6,8),"YM")) | K114: =IF(H114="","",DATEDIF(H114,DATE(2027,4,8),"Y")) | L114: =IF(H114="","",DATEDIF(H114,DATE(2027,4,8),"YM")) | M114: F

Sheet _SF9_LEARNER_LIST
A1: {=IFERROR(IF(ROWS($A$1:A1)<=COUNTA('INPUT DATA'!$L$11:$L$60),INDEX('INPUT DATA'!$L$11:$L$60,_xludf.AGGREGATE(15,6,(ROW('INPUT DATA'!$L$11:$L$60)-ROW('INPUT DATA'!$L$11)+1)/('INPUT DATA'!$L$11:$L$60<>""),ROWS($A$1:A1))),INDEX('INPUT DATA'!$Q$11:$Q$60,_xludf.AGGREGATE(15,6,(ROW('INPUT DATA'!$Q$11:$Q$60)-ROW('INPUT DATA'!$Q$11)+1)/('INPUT DATA'!$Q$11:$Q$60<>""),ROWS($A$1:A1)-COUNTA('INPUT DATA'!$L$11:$L$60)))),"")}
A2: {=IFERROR(IF(ROWS($A$1:A2)<=COUNTA('INPUT DATA'!$L$11:$L$60),INDEX('INPUT DATA'!$L$11:$L$60,_xludf.AGGREGATE(15,6,(ROW('INPUT DATA'!$L$11:$L$60)-ROW('INPUT DATA'!$L$11)+1)/('INPUT DATA'!$L$11:$L$60<>""),ROWS($A$1:A2))),INDEX('INPUT DATA'!$Q$11:$Q$60,_xludf.AGGREGATE(15,6,(ROW('INPUT DATA'!$Q$11:$Q$60)-ROW('INPUT DATA'!$Q$11)+1)/('INPUT DATA'!$Q$11:$Q$60<>""),ROWS($A$1:A2)-COUNTA('INPUT DATA'!$L$11:$L$60)))),"")}
A3: {=IFERROR(IF(ROWS($A$1:A3)<=COUNTA('INPUT DATA'!$L$11:$L$60),INDEX('INPUT DATA'!$L$11:$L$60,_xludf.AGGREGATE(15,6,(ROW('INPUT DATA'!$L$11:$L$60)-ROW('INPUT DATA'!$L$11)+1)/('INPUT DATA'!$L$11:$L$60<>""),ROWS($A$1:A3))),INDEX('INPUT DATA'!$Q$11:$Q$60,_xludf.AGGREGATE(15,6,(ROW('INPUT DATA'!$Q$11:$Q$60)-ROW('INPUT DATA'!$Q$11)+1)/('INPUT DATA'!$Q$11:$Q$60<>""),ROWS($A$1:A3)-COUNTA('INPUT DATA'!$L$11:$L$60)))),"")}
A4: {=IFERROR(IF(ROWS($A$1:A4)<=COUNTA('INPUT DATA'!$L$11:$L$60),INDEX('INPUT DATA'!$L$11:$L$60,_xludf.AGGREGATE(15,6,(ROW('INPUT DATA'!$L$11:$L$60)-ROW('INPUT DATA'!$L$11)+1)/('INPUT DATA'!$L$11:$L$60<>""),ROWS($A$1:A4))),INDEX('INPUT DATA'!$Q$11:$Q$60,_xludf.AGGREGATE(15,6,(ROW('INPUT DATA'!$Q$11:$Q$60)-ROW('INPUT DATA'!$Q$11)+1)/('INPUT DATA'!$Q$11:$Q$60<>""),ROWS($A$1:A4)-COUNTA('INPUT DATA'!$L$11:$L$60)))),"")}
A5: {=IFERROR(IF(ROWS($A$1:A5)<=COUNTA('INPUT DATA'!$L$11:$L$60),INDEX('INPUT DATA'!$L$11:$L$60,_xludf.AGGREGATE(15,6,(ROW('INPUT DATA'!$L$11:$L$60)-ROW('INPUT DATA'!$L$11)+1)/('INPUT DATA'!$L$11:$L$60<>""),ROWS($A$1:A5))),INDEX('INPUT DATA'!$Q$11:$Q$60,_xludf.AGGREGATE(15,6,(ROW('INPUT DATA'!$Q$11:$Q$60)-ROW('INPUT DATA'!$Q$11)+1)/('INPUT DATA'!$Q$11:$Q$60<>""),ROWS($A$1:A5)-COUNTA('INPUT DATA'!$L$11:$L$60)))),"")}
A6: {=IFERROR(IF(ROWS($A$1:A6)<=COUNTA('INPUT DATA'!$L$11:$L$60),INDEX('INPUT DATA'!$L$11:$L$60,_xludf.AGGREGATE(15,6,(ROW('INPUT DATA'!$L$11:$L$60)-ROW('INPUT DATA'!$L$11)+1)/('INPUT DATA'!$L$11:$L$60<>""),ROWS($A$1:A6))),INDEX('INPUT DATA'!$Q$11:$Q$60,_xludf.AGGREGATE(15,6,(ROW('INPUT DATA'!$Q$11:$Q$60)-ROW('INPUT DATA'!$Q$11)+1)/('INPUT DATA'!$Q$11:$Q$60<>""),ROWS($A$1:A6)-COUNTA('INPUT DATA'!$L$11:$L$60)))),"")}
A7: {=IFERROR(IF(ROWS($A$1:A7)<=COUNTA('INPUT DATA'!$L$11:$L$60),INDEX('INPUT DATA'!$L$11:$L$60,_xludf.AGGREGATE(15,6,(ROW('INPUT DATA'!$L$11:$L$60)-ROW('INPUT DATA'!$L$11)+1)/('INPUT DATA'!$L$11:$L$60<>""),ROWS($A$1:A7))),INDEX('INPUT DATA'!$Q$11:$Q$60,_xludf.AGGREGATE(15,6,(ROW('INPUT DATA'!$Q$11:$Q$60)-ROW('INPUT DATA'!$Q$11)+1)/('INPUT DATA'!$Q$11:$Q$60<>""),ROWS($A$1:A7)-COUNTA('INPUT DATA'!$L$11:$L$60)))),"")}
A8: {=IFERROR(IF(ROWS($A$1:A8)<=COUNTA('INPUT DATA'!$L$11:$L$60),INDEX('INPUT DATA'!$L$11:$L$60,_xludf.AGGREGATE(15,6,(ROW('INPUT DATA'!$L$11:$L$60)-ROW('INPUT DATA'!$L$11)+1)/('INPUT DATA'!$L$11:$L$60<>""),ROWS($A$1:A8))),INDEX('INPUT DATA'!$Q$11:$Q$60,_xludf.AGGREGATE(15,6,(ROW('INPUT DATA'!$Q$11:$Q$60)-ROW('INPUT DATA'!$Q$11)+1)/('INPUT DATA'!$Q$11:$Q$60<>""),ROWS($A$1:A8)-COUNTA('INPUT DATA'!$L$11:$L$60)))),"")}
A9: {=IFERROR(IF(ROWS($A$1:A9)<=COUNTA('INPUT DATA'!$L$11:$L$60),INDEX('INPUT DATA'!$L$11:$L$60,_xludf.AGGREGATE(15,6,(ROW('INPUT DATA'!$L$11:$L$60)-ROW('INPUT DATA'!$L$11)+1)/('INPUT DATA'!$L$11:$L$60<>""),ROWS($A$1:A9))),INDEX('INPUT DATA'!$Q$11:$Q$60,_xludf.AGGREGATE(15,6,(ROW('INPUT DATA'!$Q$11:$Q$60)-ROW('INPUT DATA'!$Q$11)+1)/('INPUT DATA'!$Q$11:$Q$60<>""),ROWS($A$1:A9)-COUNTA('INPUT DATA'!$L$11:$L$60)))),"")}
A10: {=IFERROR(IF(ROWS($A$1:A10)<=COUNTA('INPUT DATA'!$L$11:$L$60),INDEX('INPUT DATA'!$L$11:$L$60,_xludf.AGGREGATE(15,6,(ROW('INPUT DATA'!$L$11:$L$60)-ROW('INPUT DATA'!$L$11)+1)/('INPUT DATA'!$L$11:$L$60<>""),ROWS($A$1:A10))),INDEX('INPUT DATA'!$Q$11:$Q$60,_xludf.AGGREGATE(15,6,(ROW('INPUT DATA'!$Q$11:$Q$60)-ROW('INPUT DATA'!$Q$11)+1)/('INPUT DATA'!$Q$11:$Q$60<>""),ROWS($A$1:A10)-COUNTA('INPUT DATA'!$L$11:$L$60)))),"")}
A11: {=IFERROR(IF(ROWS($A$1:A11)<=COUNTA('INPUT DATA'!$L$11:$L$60),INDEX('INPUT DATA'!$L$11:$L$60,_xludf.AGGREGATE(15,6,(ROW('INPUT DATA'!$L$11:$L$60)-ROW('INPUT DATA'!$L$11)+1)/('INPUT DATA'!$L$11:$L$60<>""),ROWS($A$1:A11))),INDEX('INPUT DATA'!$Q$11:$Q$60,_xludf.AGGREGATE(15,6,(ROW('INPUT DATA'!$Q$11:$Q$60)-ROW('INPUT DATA'!$Q$11)+1)/('INPUT DATA'!$Q$11:$Q$60<>""),ROWS($A$1:A11)-COUNTA('INPUT DATA'!$L$11:$L$60)))),"")}
A12: {=IFERROR(IF(ROWS($A$1:A12)<=COUNTA('INPUT DATA'!$L$11:$L$60),INDEX('INPUT DATA'!$L$11:$L$60,_xludf.AGGREGATE(15,6,(ROW('INPUT DATA'!$L$11:$L$60)-ROW('INPUT DATA'!$L$11)+1)/('INPUT DATA'!$L$11:$L$60<>""),ROWS($A$1:A12))),INDEX('INPUT DATA'!$Q$11:$Q$60,_xludf.AGGREGATE(15,6,(ROW('INPUT DATA'!$Q$11:$Q$60)-ROW('INPUT DATA'!$Q$11)+1)/('INPUT DATA'!$Q$11:$Q$60<>""),ROWS($A$1:A12)-COUNTA('INPUT DATA'!$L$11:$L$60)))),"")}
... A100: {=IFERROR(IF(ROWS($A$1:A100)<=COUNTA('INPUT DATA'!$L$11:$L$60),INDEX('INPUT DATA'!$L$11:$L$60,_xludf.AGGREGATE(15,6,(ROW('INPUT DATA'!$L$11:$L$60)-ROW('INPUT DATA'!$L$11)+1)/('INPUT DATA'!$L$11:$L$60<>""),ROWS($A$1:A100))),INDEX('INPUT DATA'!$Q$11:$Q$60,_xludf.AGGREGATE(15,6,(ROW('INPUT DATA'!$Q$11:$Q$60)-ROW('INPUT DATA'!$Q$11)+1)/('INPUT DATA'!$Q$11:$Q$60<>""),ROWS($A$1:A100)-COUNTA('INPUT DATA'!$L$11:$L$60)))),"")}
